<mujoco model="Softwalker">
  <option timestep="0.0025"/>

  <statistic extent="2" center="0 0 1"/>

  <!-- Include common assets for materials
  <include file="../common.xml"/> -->

  <default>
    <joint damping=".1" armature="0.01" limited="true" solimplimit="0 .99 .01"/>
    <geom contype="1" conaffinity="0" friction=".7 .1 .1"/>
    <motor ctrlrange="-1 1" ctrllimited="true"/>
    <site size="0.01"/>
    <default class="walker">
      <geom material="self" type="capsule"/>
      <joint axis="0 -1 0"/>
    </default>
  </default>

  <worldbody>
    <geom name="floor" type="plane" conaffinity="1" pos="998 0 0" size="1000 .8 .2" material="blue_grid" zaxis="0 0 1"/>
    <camera name="sideon" pos="0 -10 5" fovy="45" mode="targetbody" target="torso" />
    <camera name="float_far"  pos="-4 0 2" xyaxes="0 -1 0 .5 0 1" mode="trackcom" fovy="90"/>
    <body name="torso" pos="0 0 1.3" childclass="walker">
      <light name="light" pos="0 0 2" mode="trackcom"/>
      <camera name="floating"  pos="-2 0 1" xyaxes="0 -1 0 .5 0 1" mode="trackcom" fovy="90"/>
      <camera name="egocentric"  pos=".25 0 .11" xyaxes="0 -1 0 0 0 1" fovy="90" />
      <joint name="rootz" axis="0 0 1" type="slide" limited="false" armature="0" damping="0"/>
      <joint name="rootx" axis="1 0 0" type="slide" limited="false" armature="0" damping="0"/>
      <joint name="rooty" axis="0 1 0" type="hinge" limited="false" armature="0" damping="0"/>
      <geom name="torso" size="0.25 0.3" mass="10.673" zaxis="0 1 0"/>
      <site name="torso_site" pos="0 0 0" size="0.01"/>
      <body name="right_thigh" pos="0 -.3 -0.3">
        <joint name="right_hip" range="-20 100"/>
        <geom name="right_thigh" pos="0 0 -0.225" size="0.25 0.225" mass="4.05789"/>
        <body name="right_leg" pos="0 0 -0.7">
          <joint name="right_knee" pos="0 0 0.25" range="-150 0"/>
          <geom name="right_leg" size="0.25 0.25" mass="2.78136"/>
        </body>
      </body>
      <body name="left_thigh" pos="0 .3 -0.3" >
        <joint name="left_hip" range="-20 100"/>
        <geom name="left_thigh" pos="0 0 -0.225" size="0.25 0.225" mass="4.05789"/>
        <body name="left_leg" pos="0 0 -0.7">
          <joint name="left_knee" pos="0 0 0.25" range="-150 0"/>
          <geom name="left_leg" size="0.25 0.25" mass="2.78136"/>
        </body>
      </body>
    </body>
  </worldbody>

  <actuator>
    <motor name="right_hip" joint="right_hip" gear="100"/>
    <motor name="right_knee" joint="right_knee" gear="50"/>
    <motor name="left_hip" joint="left_hip" gear="100"/>
    <motor name="left_knee" joint="left_knee" gear="50"/>
  </actuator>
</mujoco>
